<robot xmlns:xacro="http://www.ros.org/wiki/xacro">

    <xacro:property name="wheel_joint_effort" value="5"/>
    <xacro:property name="wheel_joint_velocity" value="50"/>

    <xacro:macro name="driven_wheel2" params="num *pose *axis *origin ">
        <link name="link_driven_wheel${num}">
            <visual>
                <xacro:insert_block name="pose"/>
                <geometry>
                    <mesh filename="package://rm_description/meshes/sentry/driven_wheel2.stl"
                          scale="0.001 0.001 0.001"/>
                </geometry>
            </visual>
            <inertial>
                <mass value="0.712e-3"/>
                <origin xyz="0 0 0" rpy="0 0 0"/>
                <inertia ixx="11.315e-9" ixy="0" ixz="0" iyy="11.315e-9"
                         iyz="0" izz="19.664e-9"/>
            </inertial>
            <collision>
                <origin xyz="0 0 -0.005" rpy="0 0 0"/>
                <xacro:insert_block name="pose"/>
                <geometry>
                    <box size="0.014 0.014 0.006"/>
                </geometry>
            </collision>
        </link>

        <joint name="joint_wheel${num}" type="revolute">
            <parent link="base_link"/>
            <child link="link_driven_wheel${num}"/>
            <xacro:insert_block name="axis"/>
            <xacro:insert_block name="origin"/>
            <limit effort="${wheel_joint_effort}" velocity="${wheel_joint_velocity}" lower="-1e16" upper="1e16"/>
            <dynamics damping="0.0" friction="0.05"/>
        </joint>

    </xacro:macro>

</robot>
