<?xml version="1.0" encoding="utf-8"?>
<robot xmlns:xacro="http://www.ros.org/wiki/xacro">

    <xacro:property name="threshold" value="0.01"/>
    <xacro:property name="yaw_lower_limit" value="-3.6"/>
    <xacro:property name="yaw_upper_limit" value="1.57"/>
    <xacro:property name="pitch_lower_limit" value="-0.34"/>
    <xacro:property name="pitch_upper_limit" value="0.93"/>

    <link name="lower_yaw">
        <visual>
            <geometry>
                <mesh filename="package://rm_description/meshes/sentry/lower_yaw.stl"
                      scale="0.001 0.001 0.001"/>
            </geometry>
        </visual>
        <inertial>
            <mass value="99.15e-3"/>
            <origin xyz="-10.311e-3 -2.902e-3 -40.101e-3" rpy="0 0 0"/>
            <inertia ixx="1.456e-4" ixy="-7242.148e-9" ixz="-28572.972e-9" iyy="1.608e-4"
                     iyz="-13303.908e-9" izz="52950.519e-9"/>
        </inertial>
        <collision>
            <origin xyz="-0.166e-3 0 -49.546e-3" rpy="0 0 0"/>
            <geometry>
                <box size="0.094 0.032 0.0971"/>
            </geometry>
        </collision>
    </link>

    <joint name="lower_yaw_joint" type="revolute">
        <parent link="base_link"/>
        <child link="lower_yaw"/>
        <axis xyz="0 0 1"/>
        <origin xyz="0 0 -129e-3"/>
        <dynamics damping="0" friction="0.1"/>
        <limit effort="1.2" velocity="34" lower="${yaw_lower_limit}" upper="${yaw_upper_limit}"/>
        <safety_controller k_position="100" k_velocity="0.1"
                           soft_lower_limit="${yaw_lower_limit+threshold}"
                           soft_upper_limit="${yaw_upper_limit-threshold}"/>
    </joint>

    <link name="lower_pitch">
        <inertial>
            <mass value="809.574e-3"/>
            <origin xyz="21.588e-3 -0.686e-3 -30.256e-3"/>
            <inertia ixx="2.031e-3" ixy="-27414.264e-9" ixz="-55245.014e-9" iyy="6.195e-3"
                     iyz="31445.023e-9" izz="4.728e-3"/>
        </inertial>
        <visual>
            <origin xyz="0 0 0" rpy="0 0 0"/>
            <geometry>
                <mesh filename="package://rm_description/meshes/sentry/lower_pitch.stl" scale="0.001 0.001 0.001"/>
            </geometry>
        </visual>
        <collision>
            <origin xyz="-0.014 0 -0.066" rpy="0 0 0"/>
            <geometry>
                <box size="0.25 0.075 0.064"/>
            </geometry>
        </collision>
        <collision>
            <origin xyz="77.07e-3 -1.201e-3 0" rpy="0 0 0"/>
            <geometry>
                <box size="0.21488 0.134 0.064"/>
            </geometry>
        </collision>
        <collision>
            <origin xyz="-58e-3 -13e-3 64e-3" rpy="0 0 0"/>
            <geometry>
                <box size="0.042 0.059 0.042"/>
            </geometry>
        </collision>
    </link>

    <joint name="lower_pitch_joint" type="revolute">
        <parent link="lower_yaw"/>
        <child link="lower_pitch"/>
        <axis xyz="0 1 0"/>
        <origin xyz="0 0 -87.993e-3"/>
        <dynamics damping="0" friction="0.1"/>
        <limit effort="3." velocity="86" lower="${pitch_lower_limit}" upper="${pitch_upper_limit}"/>
        <safety_controller k_position="100" k_velocity="0.1"
                           soft_lower_limit="${pitch_lower_limit+threshold}"
                           soft_upper_limit="${pitch_upper_limit-threshold}"/>
    </joint>

    <link name="lower_camera">
        <inertial>
            <mass value="0.111"/>
            <origin xyz="24.789e-3 -0.019e-3 -14.471e-3"/>
            <inertia ixx="15645.374e-9" ixy="-94.19e-9" ixz="143.444e-9" iyy="80877.924e-9"
                     iyz="-45.908e-9" izz="80823.702e-9"/>
        </inertial>
        <visual>
            <origin xyz=" 0 0 0 " rpy="0 0 0"/>
            <geometry>
                <mesh filename="package://rm_description/meshes/sentry/lower_camera.stl" scale="0.001 0.001 0.001"/>
            </geometry>
        </visual>
        <!--<collision>
          <origin xyz="0 0 -0.015" rpy="0 0 0"/>
          <geometry>
            <box size="0.0892 0.04 0.04"/>
          </geometry>
        </collision>-->
    </link>

    <joint name="lower_camera_joint" type="fixed">
        <parent link="lower_pitch"/>
        <child link="lower_camera"/>
        <origin xyz="19.642e-3 0 -54.20e-3" rpy="0 0 0"/>
        <axis xyz="0 0 1"/>
    </joint>

</robot>
