<robot xmlns:xacro="http://www.ros.org/wiki/xacro">

  <xacro:include filename="$(find rm_description)/urdf/common/friction.urdf.xacro"/>


  <xacro:property name="wheel_offset_x" value="0.047"/>
  <xacro:property name="wheel_offset_y" value="-0.0365"/>
  <xacro:property name="wheel_offset_z" value="-0.4e-3"/>


  <xacro:friction_wheel prefixs="lower_left" connected_to="lower_pitch"
                        wheel_x_offset="${wheel_offset_x}" wheel_y_offset="${-wheel_offset_y}"
                        wheel_z_offset="${wheel_offset_z}"/>

  <xacro:friction_wheel prefixs="lower_right" connected_to="lower_pitch"
                        wheel_x_offset="${wheel_offset_x}" wheel_y_offset="${wheel_offset_y}"
                        wheel_z_offset="${wheel_offset_z}"/>


  <link name="lower_trigger">
    <inertial>
      <mass value="304.224e-3"/>
      <origin xyz="-1.589e-3 0.036e-3 -24.868e-3"/>
      <inertia ixx="3.630e-4" ixy="282.096e-9" ixz="-1745.045e-9" iyy="2.304e-4"
               iyz="463.877e-9" izz="4.276e-4"/>
    </inertial>
    <visual>
      <origin xyz="0 0 0" rpy="0 0 0"/>
      <geometry>
        <mesh filename="package://rm_description/meshes/sentry/lower_trigger.stl" scale="0.001 0.001 0.001"/>
      </geometry>
    </visual>
    <collision>
      <origin xyz="0.005 0 -0.02" rpy="0 0 0"/>
      <geometry>
        <box size="0.106 0.1 0.0663"/>
      </geometry>
    </collision>
  </link>

  <joint name="lower_trigger_joint" type="continuous">
    <origin xyz="0 148.02e-3 -29.5e-3" rpy="0 0 0"/>
    <dynamics damping="0.0" friction="0.01"/>
    <parent link="base_link"/>
    <child link="lower_trigger"/>
    <axis xyz="0 0 1 "/>
  </joint>


</robot>
