<?xml version="1.0" encoding="utf-8"?>
<robot xmlns:xacro="http://www.ros.org/wiki/xacro">

    <xacro:property name="threshold" value="0.05"/>
    <xacro:property name="yaw_lower_limit" value="-2.63"/>
    <xacro:property name="yaw_upper_limit" value="2.56"/>
    <xacro:property name="pitch_lower_limit" value="-999"/>
    <xacro:property name="pitch_upper_limit" value="999"/>

    <link name="upper_yaw">
        <visual>
            <geometry>
                <mesh filename="package://rm_description/meshes/sentry/upper_yaw.stl"
                      scale="0.001 0.001 0.001"/>
            </geometry>
        </visual>
        <inertial>
            <mass value="173.01e-3"/>
            <origin xyz="-20.009e-3 23.734e-3 62.295e-3" rpy="0 0 0"/>
            <inertia ixx="8.0227e-4" ixy="1.063e-4" ixz="2.307e-4" iyy="7.448e-4"
                     iyz="-2.615e-4" izz="3.223e-4"/>
        </inertial>
        <collision>
            <origin xyz="-0.074 0.0925 0.107" rpy="0 0 0"/>
            <geometry>
                <box size="0.045 0.045 0.035"/>
            </geometry>
        </collision>
        <collision>
            <origin xyz="-0.166e-3 0 49.546e-3" rpy="0 0 0"/>
            <geometry>
                <box size="0.094 0.032 0.0971"/>
            </geometry>
        </collision>
    </link>

    <joint name="upper_yaw_joint" type="revolute">
        <parent link="base_link"/>
        <child link="upper_yaw"/>
        <axis xyz="0 0 1"/>
        <origin xyz="0 -24.464e-3 228.5e-3"/>
        <dynamics damping="0" friction="0.1"/>
        <limit effort="1.2" velocity="13.82" lower="${yaw_lower_limit}" upper="${yaw_upper_limit}"/>
        <safety_controller k_position="100" k_velocity="0.1"
                           soft_lower_limit="${yaw_lower_limit+threshold}"
                           soft_upper_limit="${yaw_upper_limit-threshold}"/>
    </joint>

    <link name="upper_pitch">
        <inertial>
            <mass value="809.574e-3"/>
            <origin xyz="21.588e-3 0.686e-3 30.256e-3"/>
            <inertia ixx="2.031e-3" ixy="27414.264e-9" ixz="55245.014e-9" iyy="6.195e-3"
                     iyz="31445.023e-9" izz="4.728e-3"/>
        </inertial>
        <visual>
            <origin xyz="0 0 0" rpy="0 0 0"/>
            <geometry>
                <mesh filename="package://rm_description/meshes/sentry/upper_pitch.stl" scale="0.001 0.001 0.001"/>
            </geometry>
        </visual>
        <collision>
            <origin xyz="-0.014 0 0.066" rpy="0 0 0"/>
            <geometry>
                <box size="0.25 0.075 0.064"/>
            </geometry>
        </collision>
        <collision>
            <origin xyz="77.07e-3 -1.201e-3 0" rpy="0 0 0"/>
            <geometry>
                <box size="0.21488 0.134 0.064"/>
            </geometry>
        </collision>
        <collision>
            <origin xyz="-58e-3 13e-3 -64e-3" rpy="0 0 0"/>
            <geometry>
                <box size="0.042 0.059 0.042"/>
            </geometry>
        </collision>
    </link>

    <joint name="upper_pitch_joint" type="revolute">
        <parent link="upper_yaw"/>
        <child link="upper_pitch"/>
        <axis xyz="0 1 0"/>
        <origin xyz="0 0 87.993e-3"/>
        <dynamics damping="0" friction="0.1"/>
        <limit effort="3." velocity="86" lower="${pitch_lower_limit}" upper="${pitch_upper_limit}"/>
        <safety_controller k_position="100" k_velocity="0.1"
                           soft_lower_limit="${pitch_lower_limit+threshold}"
                           soft_upper_limit="${pitch_upper_limit-threshold}"/>
    </joint>

    <link name="upper_camera">
        <inertial>
            <mass value="0.111"/>
            <origin xyz="24.786e-3 0.019e-3 14.471e-3"/>
            <inertia ixx="15645.374e-9" ixy="94.19e-9" ixz="-143.444e-9" iyy="80877.924e-9"
                     iyz="-45.908e-9" izz="80823.702e-9"/>
        </inertial>
        <visual>
            <origin xyz=" 0 0 0 " rpy="0 0 0"/>
            <geometry>
                <mesh filename="package://rm_description/meshes/sentry/upper_camera.stl" scale="0.001 0.001 0.001"/>
            </geometry>
        </visual>
        <!-- <collision>
          <origin xyz="0 0 0.015" rpy="0 0 0"/>
          <geometry>
            <box size="0.0892 0.04 0.04"/>
          </geometry>
        </collision>-->
    </link>

    <joint name="upper_camera_joint" type="fixed">
        <parent link="upper_pitch"/>
        <child link="upper_camera"/>
        <origin xyz="19.642e-3 0 54.20e-3" rpy="0 0 0"/>
        <axis xyz="0 0 1"/>
    </joint>

</robot>
